[2024-08-02T10:31:52.782+0000] {taskinstance.py:1157} INFO - Dependencies all met for dep_context=non-requeueable deps ti=<TaskInstance: sensor_data_pipeline.spark_streaming_job manual__2024-08-02T10:31:50.595095+00:00 [queued]>
[2024-08-02T10:31:52.788+0000] {taskinstance.py:1157} INFO - Dependencies all met for dep_context=requeueable deps ti=<TaskInstance: sensor_data_pipeline.spark_streaming_job manual__2024-08-02T10:31:50.595095+00:00 [queued]>
[2024-08-02T10:31:52.788+0000] {taskinstance.py:1359} INFO - Starting attempt 1 of 2
[2024-08-02T10:31:52.806+0000] {taskinstance.py:1380} INFO - Executing <Task(SparkSubmitOperator): spark_streaming_job> on 2024-08-02 10:31:50.595095+00:00
[2024-08-02T10:31:52.812+0000] {standard_task_runner.py:57} INFO - Started process 1120 to run task
[2024-08-02T10:31:52.815+0000] {standard_task_runner.py:84} INFO - Running: ['***', 'tasks', 'run', 'sensor_data_pipeline', 'spark_streaming_job', 'manual__2024-08-02T10:31:50.595095+00:00', '--job-id', '48', '--raw', '--subdir', 'DAGS_FOLDER/sensor_data_pipeline.py', '--cfg-path', '/tmp/tmpm15v_j5t']
[2024-08-02T10:31:52.817+0000] {standard_task_runner.py:85} INFO - Job 48: Subtask spark_streaming_job
[2024-08-02T10:31:52.862+0000] {task_command.py:415} INFO - Running <TaskInstance: sensor_data_pipeline.spark_streaming_job manual__2024-08-02T10:31:50.595095+00:00 [running]> on host 2198335290f9
[2024-08-02T10:31:52.959+0000] {taskinstance.py:1660} INFO - Exporting env vars: AIRFLOW_CTX_DAG_OWNER='***' AIRFLOW_CTX_DAG_ID='sensor_data_pipeline' AIRFLOW_CTX_TASK_ID='spark_streaming_job' AIRFLOW_CTX_EXECUTION_DATE='2024-08-02T10:31:50.595095+00:00' AIRFLOW_CTX_TRY_NUMBER='1' AIRFLOW_CTX_DAG_RUN_ID='manual__2024-08-02T10:31:50.595095+00:00'
[2024-08-02T10:31:52.970+0000] {base.py:73} INFO - Using connection ID 'spark_default' for task execution.
[2024-08-02T10:31:52.972+0000] {spark_submit.py:403} INFO - Spark-Submit cmd: spark-submit --master spark://spark-master:7077 --name arrow-spark --verbose --deploy-mode client /opt/***/dags/src/processors/sensor_data_processor.py
[2024-08-02T10:31:53.117+0000] {spark_submit.py:579} INFO - /home/***/.local/lib/python3.8/site-packages/pyspark/bin/load-spark-env.sh: line 68: ps: command not found
[2024-08-02T10:31:54.837+0000] {spark_submit.py:579} INFO - Using properties file: null
[2024-08-02T10:31:54.996+0000] {spark_submit.py:579} INFO - Parsed arguments:
[2024-08-02T10:31:54.997+0000] {spark_submit.py:579} INFO - master                  spark://spark-master:7077
[2024-08-02T10:31:54.997+0000] {spark_submit.py:579} INFO - deployMode              client
[2024-08-02T10:31:54.997+0000] {spark_submit.py:579} INFO - executorMemory          null
[2024-08-02T10:31:54.998+0000] {spark_submit.py:579} INFO - executorCores           null
[2024-08-02T10:31:54.998+0000] {spark_submit.py:579} INFO - totalExecutorCores      null
[2024-08-02T10:31:54.999+0000] {spark_submit.py:579} INFO - propertiesFile          null
[2024-08-02T10:31:54.999+0000] {spark_submit.py:579} INFO - driverMemory            null
[2024-08-02T10:31:54.999+0000] {spark_submit.py:579} INFO - driverCores             null
[2024-08-02T10:31:55.000+0000] {spark_submit.py:579} INFO - driverExtraClassPath    null
[2024-08-02T10:31:55.000+0000] {spark_submit.py:579} INFO - driverExtraLibraryPath  null
[2024-08-02T10:31:55.000+0000] {spark_submit.py:579} INFO - driverExtraJavaOptions  null
[2024-08-02T10:31:55.001+0000] {spark_submit.py:579} INFO - supervise               false
[2024-08-02T10:31:55.001+0000] {spark_submit.py:579} INFO - queue                   null
[2024-08-02T10:31:55.002+0000] {spark_submit.py:579} INFO - numExecutors            null
[2024-08-02T10:31:55.002+0000] {spark_submit.py:579} INFO - files                   null
[2024-08-02T10:31:55.002+0000] {spark_submit.py:579} INFO - pyFiles                 null
[2024-08-02T10:31:55.003+0000] {spark_submit.py:579} INFO - archives                null
[2024-08-02T10:31:55.003+0000] {spark_submit.py:579} INFO - mainClass               null
[2024-08-02T10:31:55.004+0000] {spark_submit.py:579} INFO - primaryResource         file:/opt/***/dags/src/processors/sensor_data_processor.py
[2024-08-02T10:31:55.004+0000] {spark_submit.py:579} INFO - name                    arrow-spark
[2024-08-02T10:31:55.004+0000] {spark_submit.py:579} INFO - childArgs               []
[2024-08-02T10:31:55.007+0000] {spark_submit.py:579} INFO - jars                    null
[2024-08-02T10:31:55.018+0000] {spark_submit.py:579} INFO - packages                null
[2024-08-02T10:31:55.019+0000] {spark_submit.py:579} INFO - packagesExclusions      null
[2024-08-02T10:31:55.040+0000] {spark_submit.py:579} INFO - repositories            null
[2024-08-02T10:31:55.040+0000] {spark_submit.py:579} INFO - verbose                 true
[2024-08-02T10:31:55.041+0000] {spark_submit.py:579} INFO - 
[2024-08-02T10:31:55.041+0000] {spark_submit.py:579} INFO - Spark properties used, including those specified through
[2024-08-02T10:31:55.042+0000] {spark_submit.py:579} INFO - --conf and those from the properties file null:
[2024-08-02T10:31:55.042+0000] {spark_submit.py:579} INFO - 
[2024-08-02T10:31:55.045+0000] {spark_submit.py:579} INFO - 
[2024-08-02T10:31:55.046+0000] {spark_submit.py:579} INFO - 
[2024-08-02T10:31:55.632+0000] {spark_submit.py:579} INFO - Main class:
[2024-08-02T10:31:55.633+0000] {spark_submit.py:579} INFO - org.apache.spark.deploy.PythonRunner
[2024-08-02T10:31:55.633+0000] {spark_submit.py:579} INFO - Arguments:
[2024-08-02T10:31:55.633+0000] {spark_submit.py:579} INFO - file:/opt/***/dags/src/processors/sensor_data_processor.py
[2024-08-02T10:31:55.634+0000] {spark_submit.py:579} INFO - null
[2024-08-02T10:31:55.667+0000] {spark_submit.py:579} INFO - Spark config:
[2024-08-02T10:31:55.668+0000] {spark_submit.py:579} INFO - (spark.app.name,arrow-spark)
[2024-08-02T10:31:55.668+0000] {spark_submit.py:579} INFO - (spark.app.submitTime,1722594715574)
[2024-08-02T10:31:55.668+0000] {spark_submit.py:579} INFO - (spark.master,spark://spark-master:7077)
[2024-08-02T10:31:55.668+0000] {spark_submit.py:579} INFO - (spark.submit.deployMode,client)
[2024-08-02T10:31:55.668+0000] {spark_submit.py:579} INFO - (spark.submit.pyFiles,)
[2024-08-02T10:31:55.669+0000] {spark_submit.py:579} INFO - Classpath elements:
[2024-08-02T10:31:55.669+0000] {spark_submit.py:579} INFO - 
[2024-08-02T10:31:55.670+0000] {spark_submit.py:579} INFO - 
[2024-08-02T10:31:55.670+0000] {spark_submit.py:579} INFO - 
[2024-08-02T10:31:56.540+0000] {spark_submit.py:579} INFO - 24/08/02 10:31:56 INFO SparkContext: Running Spark version 3.3.3
[2024-08-02T10:31:56.611+0000] {spark_submit.py:579} INFO - 24/08/02 10:31:56 WARN NativeCodeLoader: Unable to load native-hadoop library for your platform... using builtin-java classes where applicable
[2024-08-02T10:31:56.740+0000] {spark_submit.py:579} INFO - 24/08/02 10:31:56 INFO ResourceUtils: ==============================================================
[2024-08-02T10:31:56.741+0000] {spark_submit.py:579} INFO - 24/08/02 10:31:56 INFO ResourceUtils: No custom resources configured for spark.driver.
[2024-08-02T10:31:56.742+0000] {spark_submit.py:579} INFO - 24/08/02 10:31:56 INFO ResourceUtils: ==============================================================
[2024-08-02T10:31:56.742+0000] {spark_submit.py:579} INFO - 24/08/02 10:31:56 INFO SparkContext: Submitted application: SensorDataProcessor
[2024-08-02T10:31:56.772+0000] {spark_submit.py:579} INFO - 24/08/02 10:31:56 INFO ResourceProfile: Default ResourceProfile created, executor resources: Map(cores -> name: cores, amount: 1, script: , vendor: , memory -> name: memory, amount: 1024, script: , vendor: , offHeap -> name: offHeap, amount: 0, script: , vendor: ), task resources: Map(cpus -> name: cpus, amount: 1.0)
[2024-08-02T10:31:56.786+0000] {spark_submit.py:579} INFO - 24/08/02 10:31:56 INFO ResourceProfile: Limiting resource is cpu
[2024-08-02T10:31:56.788+0000] {spark_submit.py:579} INFO - 24/08/02 10:31:56 INFO ResourceProfileManager: Added ResourceProfile id: 0
[2024-08-02T10:31:56.852+0000] {spark_submit.py:579} INFO - 24/08/02 10:31:56 INFO SecurityManager: Changing view acls to: ***
[2024-08-02T10:31:56.853+0000] {spark_submit.py:579} INFO - 24/08/02 10:31:56 INFO SecurityManager: Changing modify acls to: ***
[2024-08-02T10:31:56.855+0000] {spark_submit.py:579} INFO - 24/08/02 10:31:56 INFO SecurityManager: Changing view acls groups to:
[2024-08-02T10:31:56.855+0000] {spark_submit.py:579} INFO - 24/08/02 10:31:56 INFO SecurityManager: Changing modify acls groups to:
[2024-08-02T10:31:56.856+0000] {spark_submit.py:579} INFO - 24/08/02 10:31:56 INFO SecurityManager: SecurityManager: authentication disabled; ui acls disabled; users  with view permissions: Set(***); groups with view permissions: Set(); users  with modify permissions: Set(***); groups with modify permissions: Set()
[2024-08-02T10:31:57.135+0000] {spark_submit.py:579} INFO - 24/08/02 10:31:57 INFO Utils: Successfully started service 'sparkDriver' on port 41357.
[2024-08-02T10:31:57.186+0000] {spark_submit.py:579} INFO - 24/08/02 10:31:57 INFO SparkEnv: Registering MapOutputTracker
[2024-08-02T10:31:57.222+0000] {spark_submit.py:579} INFO - 24/08/02 10:31:57 INFO SparkEnv: Registering BlockManagerMaster
[2024-08-02T10:31:57.266+0000] {spark_submit.py:579} INFO - 24/08/02 10:31:57 INFO BlockManagerMasterEndpoint: Using org.apache.spark.storage.DefaultTopologyMapper for getting topology information
[2024-08-02T10:31:57.267+0000] {spark_submit.py:579} INFO - 24/08/02 10:31:57 INFO BlockManagerMasterEndpoint: BlockManagerMasterEndpoint up
[2024-08-02T10:31:57.272+0000] {spark_submit.py:579} INFO - 24/08/02 10:31:57 INFO SparkEnv: Registering BlockManagerMasterHeartbeat
[2024-08-02T10:31:57.290+0000] {spark_submit.py:579} INFO - 24/08/02 10:31:57 INFO DiskBlockManager: Created local directory at /tmp/blockmgr-3232da12-93ac-4209-b18f-17719c5906e3
[2024-08-02T10:31:57.312+0000] {spark_submit.py:579} INFO - 24/08/02 10:31:57 INFO MemoryStore: MemoryStore started with capacity 434.4 MiB
[2024-08-02T10:31:57.329+0000] {spark_submit.py:579} INFO - 24/08/02 10:31:57 INFO SparkEnv: Registering OutputCommitCoordinator
[2024-08-02T10:31:57.650+0000] {spark_submit.py:579} INFO - 24/08/02 10:31:57 INFO Utils: Successfully started service 'SparkUI' on port 4040.
[2024-08-02T10:31:57.905+0000] {spark_submit.py:579} INFO - 24/08/02 10:31:57 INFO StandaloneAppClient$ClientEndpoint: Connecting to master spark://spark-master:7077...
[2024-08-02T10:31:58.075+0000] {spark_submit.py:579} INFO - 24/08/02 10:31:58 WARN StandaloneAppClient$ClientEndpoint: Failed to connect to master spark-master:7077
[2024-08-02T10:31:58.076+0000] {spark_submit.py:579} INFO - org.apache.spark.SparkException: Exception thrown in awaitResult:
[2024-08-02T10:31:58.076+0000] {spark_submit.py:579} INFO - at org.apache.spark.util.ThreadUtils$.awaitResult(ThreadUtils.scala:301)
[2024-08-02T10:31:58.077+0000] {spark_submit.py:579} INFO - at org.apache.spark.rpc.RpcTimeout.awaitResult(RpcTimeout.scala:75)
[2024-08-02T10:31:58.077+0000] {spark_submit.py:579} INFO - at org.apache.spark.rpc.RpcEnv.setupEndpointRefByURI(RpcEnv.scala:102)
[2024-08-02T10:31:58.078+0000] {spark_submit.py:579} INFO - at org.apache.spark.rpc.RpcEnv.setupEndpointRef(RpcEnv.scala:110)
[2024-08-02T10:31:58.078+0000] {spark_submit.py:579} INFO - at org.apache.spark.deploy.client.StandaloneAppClient$ClientEndpoint$$anon$1.run(StandaloneAppClient.scala:107)
[2024-08-02T10:31:58.078+0000] {spark_submit.py:579} INFO - at java.base/java.util.concurrent.Executors$RunnableAdapter.call(Executors.java:515)
[2024-08-02T10:31:58.079+0000] {spark_submit.py:579} INFO - at java.base/java.util.concurrent.FutureTask.run(FutureTask.java:264)
[2024-08-02T10:31:58.079+0000] {spark_submit.py:579} INFO - at java.base/java.util.concurrent.ThreadPoolExecutor.runWorker(ThreadPoolExecutor.java:1128)
[2024-08-02T10:31:58.080+0000] {spark_submit.py:579} INFO - at java.base/java.util.concurrent.ThreadPoolExecutor$Worker.run(ThreadPoolExecutor.java:628)
[2024-08-02T10:31:58.080+0000] {spark_submit.py:579} INFO - at java.base/java.lang.Thread.run(Thread.java:829)
[2024-08-02T10:31:58.080+0000] {spark_submit.py:579} INFO - Caused by: java.io.IOException: Failed to connect to spark-master:7077
[2024-08-02T10:31:58.081+0000] {spark_submit.py:579} INFO - at org.apache.spark.network.client.TransportClientFactory.createClient(TransportClientFactory.java:298)
[2024-08-02T10:31:58.081+0000] {spark_submit.py:579} INFO - at org.apache.spark.network.client.TransportClientFactory.createClient(TransportClientFactory.java:218)
[2024-08-02T10:31:58.082+0000] {spark_submit.py:579} INFO - at org.apache.spark.network.client.TransportClientFactory.createClient(TransportClientFactory.java:230)
[2024-08-02T10:31:58.082+0000] {spark_submit.py:579} INFO - at org.apache.spark.rpc.netty.NettyRpcEnv.createClient(NettyRpcEnv.scala:204)
[2024-08-02T10:31:58.083+0000] {spark_submit.py:579} INFO - at org.apache.spark.rpc.netty.Outbox$$anon$1.call(Outbox.scala:202)
[2024-08-02T10:31:58.083+0000] {spark_submit.py:579} INFO - at org.apache.spark.rpc.netty.Outbox$$anon$1.call(Outbox.scala:198)
[2024-08-02T10:31:58.084+0000] {spark_submit.py:579} INFO - ... 4 more
[2024-08-02T10:31:58.084+0000] {spark_submit.py:579} INFO - Caused by: java.net.UnknownHostException: spark-master
[2024-08-02T10:31:58.084+0000] {spark_submit.py:579} INFO - at java.base/java.net.InetAddress$CachedAddresses.get(InetAddress.java:797)
[2024-08-02T10:31:58.085+0000] {spark_submit.py:579} INFO - at java.base/java.net.InetAddress.getAllByName0(InetAddress.java:1533)
[2024-08-02T10:31:58.085+0000] {spark_submit.py:579} INFO - at java.base/java.net.InetAddress.getAllByName(InetAddress.java:1386)
[2024-08-02T10:31:58.085+0000] {spark_submit.py:579} INFO - at java.base/java.net.InetAddress.getAllByName(InetAddress.java:1307)
[2024-08-02T10:31:58.086+0000] {spark_submit.py:579} INFO - at java.base/java.net.InetAddress.getByName(InetAddress.java:1257)
[2024-08-02T10:31:58.086+0000] {spark_submit.py:579} INFO - at io.netty.util.internal.SocketUtils$8.run(SocketUtils.java:156)
[2024-08-02T10:31:58.087+0000] {spark_submit.py:579} INFO - at io.netty.util.internal.SocketUtils$8.run(SocketUtils.java:153)
[2024-08-02T10:31:58.087+0000] {spark_submit.py:579} INFO - at java.base/java.security.AccessController.doPrivileged(Native Method)
[2024-08-02T10:31:58.087+0000] {spark_submit.py:579} INFO - at io.netty.util.internal.SocketUtils.addressByName(SocketUtils.java:153)
[2024-08-02T10:31:58.088+0000] {spark_submit.py:579} INFO - at io.netty.resolver.DefaultNameResolver.doResolve(DefaultNameResolver.java:41)
[2024-08-02T10:31:58.088+0000] {spark_submit.py:579} INFO - at io.netty.resolver.SimpleNameResolver.resolve(SimpleNameResolver.java:61)
[2024-08-02T10:31:58.089+0000] {spark_submit.py:579} INFO - at io.netty.resolver.SimpleNameResolver.resolve(SimpleNameResolver.java:53)
[2024-08-02T10:31:58.089+0000] {spark_submit.py:579} INFO - at io.netty.resolver.InetSocketAddressResolver.doResolve(InetSocketAddressResolver.java:55)
[2024-08-02T10:31:58.089+0000] {spark_submit.py:579} INFO - at io.netty.resolver.InetSocketAddressResolver.doResolve(InetSocketAddressResolver.java:31)
[2024-08-02T10:31:58.090+0000] {spark_submit.py:579} INFO - at io.netty.resolver.AbstractAddressResolver.resolve(AbstractAddressResolver.java:106)
[2024-08-02T10:31:58.090+0000] {spark_submit.py:579} INFO - at io.netty.bootstrap.Bootstrap.doResolveAndConnect0(Bootstrap.java:206)
[2024-08-02T10:31:58.091+0000] {spark_submit.py:579} INFO - at io.netty.bootstrap.Bootstrap.access$000(Bootstrap.java:46)
[2024-08-02T10:31:58.091+0000] {spark_submit.py:579} INFO - at io.netty.bootstrap.Bootstrap$1.operationComplete(Bootstrap.java:180)
[2024-08-02T10:31:58.091+0000] {spark_submit.py:579} INFO - at io.netty.bootstrap.Bootstrap$1.operationComplete(Bootstrap.java:166)
[2024-08-02T10:31:58.091+0000] {spark_submit.py:579} INFO - at io.netty.util.concurrent.DefaultPromise.notifyListener0(DefaultPromise.java:578)
[2024-08-02T10:31:58.092+0000] {spark_submit.py:579} INFO - at io.netty.util.concurrent.DefaultPromise.notifyListenersNow(DefaultPromise.java:552)
[2024-08-02T10:31:58.092+0000] {spark_submit.py:579} INFO - at io.netty.util.concurrent.DefaultPromise.notifyListeners(DefaultPromise.java:491)
[2024-08-02T10:31:58.092+0000] {spark_submit.py:579} INFO - at io.netty.util.concurrent.DefaultPromise.setValue0(DefaultPromise.java:616)
[2024-08-02T10:31:58.092+0000] {spark_submit.py:579} INFO - at io.netty.util.concurrent.DefaultPromise.setSuccess0(DefaultPromise.java:605)
[2024-08-02T10:31:58.092+0000] {spark_submit.py:579} INFO - at io.netty.util.concurrent.DefaultPromise.trySuccess(DefaultPromise.java:104)
[2024-08-02T10:31:58.092+0000] {spark_submit.py:579} INFO - at io.netty.channel.DefaultChannelPromise.trySuccess(DefaultChannelPromise.java:84)
[2024-08-02T10:31:58.092+0000] {spark_submit.py:579} INFO - at io.netty.channel.AbstractChannel$AbstractUnsafe.safeSetSuccess(AbstractChannel.java:990)
[2024-08-02T10:31:58.093+0000] {spark_submit.py:579} INFO - at io.netty.channel.AbstractChannel$AbstractUnsafe.register0(AbstractChannel.java:516)
[2024-08-02T10:31:58.093+0000] {spark_submit.py:579} INFO - at io.netty.channel.AbstractChannel$AbstractUnsafe.access$200(AbstractChannel.java:429)
[2024-08-02T10:31:58.093+0000] {spark_submit.py:579} INFO - at io.netty.channel.AbstractChannel$AbstractUnsafe$1.run(AbstractChannel.java:486)
[2024-08-02T10:31:58.093+0000] {spark_submit.py:579} INFO - at io.netty.util.concurrent.AbstractEventExecutor.safeExecute(AbstractEventExecutor.java:164)
[2024-08-02T10:31:58.093+0000] {spark_submit.py:579} INFO - at io.netty.util.concurrent.SingleThreadEventExecutor.runAllTasks(SingleThreadEventExecutor.java:469)
[2024-08-02T10:31:58.093+0000] {spark_submit.py:579} INFO - at io.netty.channel.nio.NioEventLoop.run(NioEventLoop.java:503)
[2024-08-02T10:31:58.093+0000] {spark_submit.py:579} INFO - at io.netty.util.concurrent.SingleThreadEventExecutor$4.run(SingleThreadEventExecutor.java:986)
[2024-08-02T10:31:58.094+0000] {spark_submit.py:579} INFO - at io.netty.util.internal.ThreadExecutorMap$2.run(ThreadExecutorMap.java:74)
[2024-08-02T10:31:58.094+0000] {spark_submit.py:579} INFO - at io.netty.util.concurrent.FastThreadLocalRunnable.run(FastThreadLocalRunnable.java:30)
[2024-08-02T10:31:58.094+0000] {spark_submit.py:579} INFO - ... 1 more
[2024-08-02T10:32:17.904+0000] {spark_submit.py:579} INFO - 24/08/02 10:32:17 INFO StandaloneAppClient$ClientEndpoint: Connecting to master spark://spark-master:7077...
[2024-08-02T10:32:17.932+0000] {spark_submit.py:579} INFO - 24/08/02 10:32:17 WARN StandaloneAppClient$ClientEndpoint: Failed to connect to master spark-master:7077
[2024-08-02T10:32:17.933+0000] {spark_submit.py:579} INFO - org.apache.spark.SparkException: Exception thrown in awaitResult:
[2024-08-02T10:32:17.933+0000] {spark_submit.py:579} INFO - at org.apache.spark.util.ThreadUtils$.awaitResult(ThreadUtils.scala:301)
[2024-08-02T10:32:17.933+0000] {spark_submit.py:579} INFO - at org.apache.spark.rpc.RpcTimeout.awaitResult(RpcTimeout.scala:75)
[2024-08-02T10:32:17.934+0000] {spark_submit.py:579} INFO - at org.apache.spark.rpc.RpcEnv.setupEndpointRefByURI(RpcEnv.scala:102)
[2024-08-02T10:32:17.934+0000] {spark_submit.py:579} INFO - at org.apache.spark.rpc.RpcEnv.setupEndpointRef(RpcEnv.scala:110)
[2024-08-02T10:32:17.935+0000] {spark_submit.py:579} INFO - at org.apache.spark.deploy.client.StandaloneAppClient$ClientEndpoint$$anon$1.run(StandaloneAppClient.scala:107)
[2024-08-02T10:32:17.935+0000] {spark_submit.py:579} INFO - at java.base/java.util.concurrent.Executors$RunnableAdapter.call(Executors.java:515)
[2024-08-02T10:32:17.935+0000] {spark_submit.py:579} INFO - at java.base/java.util.concurrent.FutureTask.run(FutureTask.java:264)
[2024-08-02T10:32:17.935+0000] {spark_submit.py:579} INFO - at java.base/java.util.concurrent.ThreadPoolExecutor.runWorker(ThreadPoolExecutor.java:1128)
[2024-08-02T10:32:17.935+0000] {spark_submit.py:579} INFO - at java.base/java.util.concurrent.ThreadPoolExecutor$Worker.run(ThreadPoolExecutor.java:628)
[2024-08-02T10:32:17.936+0000] {spark_submit.py:579} INFO - at java.base/java.lang.Thread.run(Thread.java:829)
[2024-08-02T10:32:17.936+0000] {spark_submit.py:579} INFO - Caused by: java.io.IOException: Failed to connect to spark-master:7077
[2024-08-02T10:32:17.936+0000] {spark_submit.py:579} INFO - at org.apache.spark.network.client.TransportClientFactory.createClient(TransportClientFactory.java:298)
[2024-08-02T10:32:17.936+0000] {spark_submit.py:579} INFO - at org.apache.spark.network.client.TransportClientFactory.createClient(TransportClientFactory.java:218)
[2024-08-02T10:32:17.936+0000] {spark_submit.py:579} INFO - at org.apache.spark.network.client.TransportClientFactory.createClient(TransportClientFactory.java:230)
[2024-08-02T10:32:17.936+0000] {spark_submit.py:579} INFO - at org.apache.spark.rpc.netty.NettyRpcEnv.createClient(NettyRpcEnv.scala:204)
[2024-08-02T10:32:17.936+0000] {spark_submit.py:579} INFO - at org.apache.spark.rpc.netty.Outbox$$anon$1.call(Outbox.scala:202)
[2024-08-02T10:32:17.936+0000] {spark_submit.py:579} INFO - at org.apache.spark.rpc.netty.Outbox$$anon$1.call(Outbox.scala:198)
[2024-08-02T10:32:17.936+0000] {spark_submit.py:579} INFO - ... 4 more
[2024-08-02T10:32:17.937+0000] {spark_submit.py:579} INFO - Caused by: java.net.UnknownHostException: spark-master
[2024-08-02T10:32:17.937+0000] {spark_submit.py:579} INFO - at java.base/java.net.InetAddress$CachedAddresses.get(InetAddress.java:797)
[2024-08-02T10:32:17.937+0000] {spark_submit.py:579} INFO - at java.base/java.net.InetAddress.getAllByName0(InetAddress.java:1533)
[2024-08-02T10:32:17.937+0000] {spark_submit.py:579} INFO - at java.base/java.net.InetAddress.getAllByName(InetAddress.java:1386)
[2024-08-02T10:32:17.937+0000] {spark_submit.py:579} INFO - at java.base/java.net.InetAddress.getAllByName(InetAddress.java:1307)
[2024-08-02T10:32:17.937+0000] {spark_submit.py:579} INFO - at java.base/java.net.InetAddress.getByName(InetAddress.java:1257)
[2024-08-02T10:32:17.937+0000] {spark_submit.py:579} INFO - at io.netty.util.internal.SocketUtils$8.run(SocketUtils.java:156)
[2024-08-02T10:32:17.937+0000] {spark_submit.py:579} INFO - at io.netty.util.internal.SocketUtils$8.run(SocketUtils.java:153)
[2024-08-02T10:32:17.938+0000] {spark_submit.py:579} INFO - at java.base/java.security.AccessController.doPrivileged(Native Method)
[2024-08-02T10:32:17.938+0000] {spark_submit.py:579} INFO - at io.netty.util.internal.SocketUtils.addressByName(SocketUtils.java:153)
[2024-08-02T10:32:17.938+0000] {spark_submit.py:579} INFO - at io.netty.resolver.DefaultNameResolver.doResolve(DefaultNameResolver.java:41)
[2024-08-02T10:32:17.938+0000] {spark_submit.py:579} INFO - at io.netty.resolver.SimpleNameResolver.resolve(SimpleNameResolver.java:61)
[2024-08-02T10:32:17.938+0000] {spark_submit.py:579} INFO - at io.netty.resolver.SimpleNameResolver.resolve(SimpleNameResolver.java:53)
[2024-08-02T10:32:17.938+0000] {spark_submit.py:579} INFO - at io.netty.resolver.InetSocketAddressResolver.doResolve(InetSocketAddressResolver.java:55)
[2024-08-02T10:32:17.938+0000] {spark_submit.py:579} INFO - at io.netty.resolver.InetSocketAddressResolver.doResolve(InetSocketAddressResolver.java:31)
[2024-08-02T10:32:17.938+0000] {spark_submit.py:579} INFO - at io.netty.resolver.AbstractAddressResolver.resolve(AbstractAddressResolver.java:106)
[2024-08-02T10:32:17.939+0000] {spark_submit.py:579} INFO - at io.netty.bootstrap.Bootstrap.doResolveAndConnect0(Bootstrap.java:206)
[2024-08-02T10:32:17.939+0000] {spark_submit.py:579} INFO - at io.netty.bootstrap.Bootstrap.access$000(Bootstrap.java:46)
[2024-08-02T10:32:17.939+0000] {spark_submit.py:579} INFO - at io.netty.bootstrap.Bootstrap$1.operationComplete(Bootstrap.java:180)
[2024-08-02T10:32:17.939+0000] {spark_submit.py:579} INFO - at io.netty.bootstrap.Bootstrap$1.operationComplete(Bootstrap.java:166)
[2024-08-02T10:32:17.939+0000] {spark_submit.py:579} INFO - at io.netty.util.concurrent.DefaultPromise.notifyListener0(DefaultPromise.java:578)
[2024-08-02T10:32:17.939+0000] {spark_submit.py:579} INFO - at io.netty.util.concurrent.DefaultPromise.notifyListenersNow(DefaultPromise.java:552)
[2024-08-02T10:32:17.939+0000] {spark_submit.py:579} INFO - at io.netty.util.concurrent.DefaultPromise.notifyListeners(DefaultPromise.java:491)
[2024-08-02T10:32:17.939+0000] {spark_submit.py:579} INFO - at io.netty.util.concurrent.DefaultPromise.setValue0(DefaultPromise.java:616)
[2024-08-02T10:32:17.939+0000] {spark_submit.py:579} INFO - at io.netty.util.concurrent.DefaultPromise.setSuccess0(DefaultPromise.java:605)
[2024-08-02T10:32:17.940+0000] {spark_submit.py:579} INFO - at io.netty.util.concurrent.DefaultPromise.trySuccess(DefaultPromise.java:104)
[2024-08-02T10:32:17.940+0000] {spark_submit.py:579} INFO - at io.netty.channel.DefaultChannelPromise.trySuccess(DefaultChannelPromise.java:84)
[2024-08-02T10:32:17.940+0000] {spark_submit.py:579} INFO - at io.netty.channel.AbstractChannel$AbstractUnsafe.safeSetSuccess(AbstractChannel.java:990)
[2024-08-02T10:32:17.940+0000] {spark_submit.py:579} INFO - at io.netty.channel.AbstractChannel$AbstractUnsafe.register0(AbstractChannel.java:516)
[2024-08-02T10:32:17.940+0000] {spark_submit.py:579} INFO - at io.netty.channel.AbstractChannel$AbstractUnsafe.access$200(AbstractChannel.java:429)
[2024-08-02T10:32:17.940+0000] {spark_submit.py:579} INFO - at io.netty.channel.AbstractChannel$AbstractUnsafe$1.run(AbstractChannel.java:486)
[2024-08-02T10:32:17.940+0000] {spark_submit.py:579} INFO - at io.netty.util.concurrent.AbstractEventExecutor.safeExecute(AbstractEventExecutor.java:164)
[2024-08-02T10:32:17.940+0000] {spark_submit.py:579} INFO - at io.netty.util.concurrent.SingleThreadEventExecutor.runAllTasks(SingleThreadEventExecutor.java:469)
[2024-08-02T10:32:17.940+0000] {spark_submit.py:579} INFO - at io.netty.channel.nio.NioEventLoop.run(NioEventLoop.java:503)
[2024-08-02T10:32:17.941+0000] {spark_submit.py:579} INFO - at io.netty.util.concurrent.SingleThreadEventExecutor$4.run(SingleThreadEventExecutor.java:986)
[2024-08-02T10:32:17.941+0000] {spark_submit.py:579} INFO - at io.netty.util.internal.ThreadExecutorMap$2.run(ThreadExecutorMap.java:74)
[2024-08-02T10:32:17.941+0000] {spark_submit.py:579} INFO - at io.netty.util.concurrent.FastThreadLocalRunnable.run(FastThreadLocalRunnable.java:30)
[2024-08-02T10:32:17.941+0000] {spark_submit.py:579} INFO - ... 1 more
[2024-08-02T10:32:23.156+0000] {job.py:219} ERROR - Job heartbeat got an exception
Traceback (most recent call last):
  File "/home/airflow/.local/lib/python3.8/site-packages/sqlalchemy/engine/base.py", line 3371, in _wrap_pool_connect
    return fn()
  File "/home/airflow/.local/lib/python3.8/site-packages/sqlalchemy/pool/base.py", line 327, in connect
    return _ConnectionFairy._checkout(self)
  File "/home/airflow/.local/lib/python3.8/site-packages/sqlalchemy/pool/base.py", line 894, in _checkout
    fairy = _ConnectionRecord.checkout(pool)
  File "/home/airflow/.local/lib/python3.8/site-packages/sqlalchemy/pool/base.py", line 493, in checkout
    rec = pool._do_get()
  File "/home/airflow/.local/lib/python3.8/site-packages/sqlalchemy/pool/impl.py", line 256, in _do_get
    return self._create_connection()
  File "/home/airflow/.local/lib/python3.8/site-packages/sqlalchemy/pool/base.py", line 273, in _create_connection
    return _ConnectionRecord(self)
  File "/home/airflow/.local/lib/python3.8/site-packages/sqlalchemy/pool/base.py", line 388, in __init__
    self.__connect()
  File "/home/airflow/.local/lib/python3.8/site-packages/sqlalchemy/pool/base.py", line 691, in __connect
    pool.logger.debug("Error on connect(): %s", e)
  File "/home/airflow/.local/lib/python3.8/site-packages/sqlalchemy/util/langhelpers.py", line 70, in __exit__
    compat.raise_(
  File "/home/airflow/.local/lib/python3.8/site-packages/sqlalchemy/util/compat.py", line 211, in raise_
    raise exception
  File "/home/airflow/.local/lib/python3.8/site-packages/sqlalchemy/pool/base.py", line 686, in __connect
    self.dbapi_connection = connection = pool._invoke_creator(self)
  File "/home/airflow/.local/lib/python3.8/site-packages/sqlalchemy/engine/create.py", line 574, in connect
    return dialect.connect(*cargs, **cparams)
  File "/home/airflow/.local/lib/python3.8/site-packages/sqlalchemy/engine/default.py", line 598, in connect
    return self.dbapi.connect(*cargs, **cparams)
  File "/home/airflow/.local/lib/python3.8/site-packages/psycopg2/__init__.py", line 122, in connect
    conn = _connect(dsn, connection_factory=connection_factory, **kwasync)
psycopg2.OperationalError: connection to server at "postgres" (172.19.0.2), port 5432 failed: FATAL:  password authentication failed for user "***"


The above exception was the direct cause of the following exception:

Traceback (most recent call last):
  File "/home/airflow/.local/lib/python3.8/site-packages/airflow/jobs/job.py", line 190, in heartbeat
    session.merge(self)
  File "/home/airflow/.local/lib/python3.8/site-packages/sqlalchemy/orm/session.py", line 3056, in merge
    return self._merge(
  File "/home/airflow/.local/lib/python3.8/site-packages/sqlalchemy/orm/session.py", line 3136, in _merge
    merged = self.get(
  File "/home/airflow/.local/lib/python3.8/site-packages/sqlalchemy/orm/session.py", line 2853, in get
    return self._get_impl(
  File "/home/airflow/.local/lib/python3.8/site-packages/sqlalchemy/orm/session.py", line 2975, in _get_impl
    return db_load_fn(
  File "/home/airflow/.local/lib/python3.8/site-packages/sqlalchemy/orm/loading.py", line 530, in load_on_pk_identity
    session.execute(
  File "/home/airflow/.local/lib/python3.8/site-packages/sqlalchemy/orm/session.py", line 1716, in execute
    conn = self._connection_for_bind(bind)
  File "/home/airflow/.local/lib/python3.8/site-packages/sqlalchemy/orm/session.py", line 1555, in _connection_for_bind
    return self._transaction._connection_for_bind(
  File "/home/airflow/.local/lib/python3.8/site-packages/sqlalchemy/orm/session.py", line 750, in _connection_for_bind
    conn = bind.connect()
  File "/home/airflow/.local/lib/python3.8/site-packages/sqlalchemy/future/engine.py", line 406, in connect
    return super(Engine, self).connect()
  File "/home/airflow/.local/lib/python3.8/site-packages/sqlalchemy/engine/base.py", line 3325, in connect
    return self._connection_cls(self, close_with_result=close_with_result)
  File "/home/airflow/.local/lib/python3.8/site-packages/sqlalchemy/engine/base.py", line 96, in __init__
    else engine.raw_connection()
  File "/home/airflow/.local/lib/python3.8/site-packages/sqlalchemy/engine/base.py", line 3404, in raw_connection
    return self._wrap_pool_connect(self.pool.connect, _connection)
  File "/home/airflow/.local/lib/python3.8/site-packages/sqlalchemy/engine/base.py", line 3374, in _wrap_pool_connect
    Connection._handle_dbapi_exception_noconnection(
  File "/home/airflow/.local/lib/python3.8/site-packages/sqlalchemy/engine/base.py", line 2208, in _handle_dbapi_exception_noconnection
    util.raise_(
  File "/home/airflow/.local/lib/python3.8/site-packages/sqlalchemy/util/compat.py", line 211, in raise_
    raise exception
  File "/home/airflow/.local/lib/python3.8/site-packages/sqlalchemy/engine/base.py", line 3371, in _wrap_pool_connect
    return fn()
  File "/home/airflow/.local/lib/python3.8/site-packages/sqlalchemy/pool/base.py", line 327, in connect
    return _ConnectionFairy._checkout(self)
  File "/home/airflow/.local/lib/python3.8/site-packages/sqlalchemy/pool/base.py", line 894, in _checkout
    fairy = _ConnectionRecord.checkout(pool)
  File "/home/airflow/.local/lib/python3.8/site-packages/sqlalchemy/pool/base.py", line 493, in checkout
    rec = pool._do_get()
  File "/home/airflow/.local/lib/python3.8/site-packages/sqlalchemy/pool/impl.py", line 256, in _do_get
    return self._create_connection()
  File "/home/airflow/.local/lib/python3.8/site-packages/sqlalchemy/pool/base.py", line 273, in _create_connection
    return _ConnectionRecord(self)
  File "/home/airflow/.local/lib/python3.8/site-packages/sqlalchemy/pool/base.py", line 388, in __init__
    self.__connect()
  File "/home/airflow/.local/lib/python3.8/site-packages/sqlalchemy/pool/base.py", line 691, in __connect
    pool.logger.debug("Error on connect(): %s", e)
  File "/home/airflow/.local/lib/python3.8/site-packages/sqlalchemy/util/langhelpers.py", line 70, in __exit__
    compat.raise_(
  File "/home/airflow/.local/lib/python3.8/site-packages/sqlalchemy/util/compat.py", line 211, in raise_
    raise exception
  File "/home/airflow/.local/lib/python3.8/site-packages/sqlalchemy/pool/base.py", line 686, in __connect
    self.dbapi_connection = connection = pool._invoke_creator(self)
  File "/home/airflow/.local/lib/python3.8/site-packages/sqlalchemy/engine/create.py", line 574, in connect
    return dialect.connect(*cargs, **cparams)
  File "/home/airflow/.local/lib/python3.8/site-packages/sqlalchemy/engine/default.py", line 598, in connect
    return self.dbapi.connect(*cargs, **cparams)
  File "/home/airflow/.local/lib/python3.8/site-packages/psycopg2/__init__.py", line 122, in connect
    conn = _connect(dsn, connection_factory=connection_factory, **kwasync)
sqlalchemy.exc.OperationalError: (psycopg2.OperationalError) connection to server at "postgres" (172.19.0.2), port 5432 failed: FATAL:  password authentication failed for user "***"

(Background on this error at: https://sqlalche.me/e/14/e3q8)
[2024-08-02T10:32:28.208+0000] {job.py:219} ERROR - Job heartbeat got an exception
Traceback (most recent call last):
  File "/home/airflow/.local/lib/python3.8/site-packages/sqlalchemy/engine/base.py", line 3371, in _wrap_pool_connect
    return fn()
  File "/home/airflow/.local/lib/python3.8/site-packages/sqlalchemy/pool/base.py", line 327, in connect
    return _ConnectionFairy._checkout(self)
  File "/home/airflow/.local/lib/python3.8/site-packages/sqlalchemy/pool/base.py", line 894, in _checkout
    fairy = _ConnectionRecord.checkout(pool)
  File "/home/airflow/.local/lib/python3.8/site-packages/sqlalchemy/pool/base.py", line 493, in checkout
    rec = pool._do_get()
  File "/home/airflow/.local/lib/python3.8/site-packages/sqlalchemy/pool/impl.py", line 256, in _do_get
    return self._create_connection()
  File "/home/airflow/.local/lib/python3.8/site-packages/sqlalchemy/pool/base.py", line 273, in _create_connection
    return _ConnectionRecord(self)
  File "/home/airflow/.local/lib/python3.8/site-packages/sqlalchemy/pool/base.py", line 388, in __init__
    self.__connect()
  File "/home/airflow/.local/lib/python3.8/site-packages/sqlalchemy/pool/base.py", line 691, in __connect
    pool.logger.debug("Error on connect(): %s", e)
  File "/home/airflow/.local/lib/python3.8/site-packages/sqlalchemy/util/langhelpers.py", line 70, in __exit__
    compat.raise_(
  File "/home/airflow/.local/lib/python3.8/site-packages/sqlalchemy/util/compat.py", line 211, in raise_
    raise exception
  File "/home/airflow/.local/lib/python3.8/site-packages/sqlalchemy/pool/base.py", line 686, in __connect
    self.dbapi_connection = connection = pool._invoke_creator(self)
  File "/home/airflow/.local/lib/python3.8/site-packages/sqlalchemy/engine/create.py", line 574, in connect
    return dialect.connect(*cargs, **cparams)
  File "/home/airflow/.local/lib/python3.8/site-packages/sqlalchemy/engine/default.py", line 598, in connect
    return self.dbapi.connect(*cargs, **cparams)
  File "/home/airflow/.local/lib/python3.8/site-packages/psycopg2/__init__.py", line 122, in connect
    conn = _connect(dsn, connection_factory=connection_factory, **kwasync)
psycopg2.OperationalError: connection to server at "postgres" (172.19.0.2), port 5432 failed: FATAL:  password authentication failed for user "***"


The above exception was the direct cause of the following exception:

Traceback (most recent call last):
  File "/home/airflow/.local/lib/python3.8/site-packages/airflow/jobs/job.py", line 190, in heartbeat
    session.merge(self)
  File "/home/airflow/.local/lib/python3.8/site-packages/sqlalchemy/orm/session.py", line 3056, in merge
    return self._merge(
  File "/home/airflow/.local/lib/python3.8/site-packages/sqlalchemy/orm/session.py", line 3136, in _merge
    merged = self.get(
  File "/home/airflow/.local/lib/python3.8/site-packages/sqlalchemy/orm/session.py", line 2853, in get
    return self._get_impl(
  File "/home/airflow/.local/lib/python3.8/site-packages/sqlalchemy/orm/session.py", line 2975, in _get_impl
    return db_load_fn(
  File "/home/airflow/.local/lib/python3.8/site-packages/sqlalchemy/orm/loading.py", line 530, in load_on_pk_identity
    session.execute(
  File "/home/airflow/.local/lib/python3.8/site-packages/sqlalchemy/orm/session.py", line 1716, in execute
    conn = self._connection_for_bind(bind)
  File "/home/airflow/.local/lib/python3.8/site-packages/sqlalchemy/orm/session.py", line 1555, in _connection_for_bind
    return self._transaction._connection_for_bind(
  File "/home/airflow/.local/lib/python3.8/site-packages/sqlalchemy/orm/session.py", line 750, in _connection_for_bind
    conn = bind.connect()
  File "/home/airflow/.local/lib/python3.8/site-packages/sqlalchemy/future/engine.py", line 406, in connect
    return super(Engine, self).connect()
  File "/home/airflow/.local/lib/python3.8/site-packages/sqlalchemy/engine/base.py", line 3325, in connect
    return self._connection_cls(self, close_with_result=close_with_result)
  File "/home/airflow/.local/lib/python3.8/site-packages/sqlalchemy/engine/base.py", line 96, in __init__
    else engine.raw_connection()
  File "/home/airflow/.local/lib/python3.8/site-packages/sqlalchemy/engine/base.py", line 3404, in raw_connection
    return self._wrap_pool_connect(self.pool.connect, _connection)
  File "/home/airflow/.local/lib/python3.8/site-packages/sqlalchemy/engine/base.py", line 3374, in _wrap_pool_connect
    Connection._handle_dbapi_exception_noconnection(
  File "/home/airflow/.local/lib/python3.8/site-packages/sqlalchemy/engine/base.py", line 2208, in _handle_dbapi_exception_noconnection
    util.raise_(
  File "/home/airflow/.local/lib/python3.8/site-packages/sqlalchemy/util/compat.py", line 211, in raise_
    raise exception
  File "/home/airflow/.local/lib/python3.8/site-packages/sqlalchemy/engine/base.py", line 3371, in _wrap_pool_connect
    return fn()
  File "/home/airflow/.local/lib/python3.8/site-packages/sqlalchemy/pool/base.py", line 327, in connect
    return _ConnectionFairy._checkout(self)
  File "/home/airflow/.local/lib/python3.8/site-packages/sqlalchemy/pool/base.py", line 894, in _checkout
    fairy = _ConnectionRecord.checkout(pool)
  File "/home/airflow/.local/lib/python3.8/site-packages/sqlalchemy/pool/base.py", line 493, in checkout
    rec = pool._do_get()
  File "/home/airflow/.local/lib/python3.8/site-packages/sqlalchemy/pool/impl.py", line 256, in _do_get
    return self._create_connection()
  File "/home/airflow/.local/lib/python3.8/site-packages/sqlalchemy/pool/base.py", line 273, in _create_connection
    return _ConnectionRecord(self)
  File "/home/airflow/.local/lib/python3.8/site-packages/sqlalchemy/pool/base.py", line 388, in __init__
    self.__connect()
  File "/home/airflow/.local/lib/python3.8/site-packages/sqlalchemy/pool/base.py", line 691, in __connect
    pool.logger.debug("Error on connect(): %s", e)
  File "/home/airflow/.local/lib/python3.8/site-packages/sqlalchemy/util/langhelpers.py", line 70, in __exit__
    compat.raise_(
  File "/home/airflow/.local/lib/python3.8/site-packages/sqlalchemy/util/compat.py", line 211, in raise_
    raise exception
  File "/home/airflow/.local/lib/python3.8/site-packages/sqlalchemy/pool/base.py", line 686, in __connect
    self.dbapi_connection = connection = pool._invoke_creator(self)
  File "/home/airflow/.local/lib/python3.8/site-packages/sqlalchemy/engine/create.py", line 574, in connect
    return dialect.connect(*cargs, **cparams)
  File "/home/airflow/.local/lib/python3.8/site-packages/sqlalchemy/engine/default.py", line 598, in connect
    return self.dbapi.connect(*cargs, **cparams)
  File "/home/airflow/.local/lib/python3.8/site-packages/psycopg2/__init__.py", line 122, in connect
    conn = _connect(dsn, connection_factory=connection_factory, **kwasync)
sqlalchemy.exc.OperationalError: (psycopg2.OperationalError) connection to server at "postgres" (172.19.0.2), port 5432 failed: FATAL:  password authentication failed for user "***"

(Background on this error at: https://sqlalche.me/e/14/e3q8)
[2024-08-02T10:32:33.241+0000] {job.py:219} ERROR - Job heartbeat got an exception
Traceback (most recent call last):
  File "/home/airflow/.local/lib/python3.8/site-packages/sqlalchemy/engine/base.py", line 3371, in _wrap_pool_connect
    return fn()
  File "/home/airflow/.local/lib/python3.8/site-packages/sqlalchemy/pool/base.py", line 327, in connect
    return _ConnectionFairy._checkout(self)
  File "/home/airflow/.local/lib/python3.8/site-packages/sqlalchemy/pool/base.py", line 894, in _checkout
    fairy = _ConnectionRecord.checkout(pool)
  File "/home/airflow/.local/lib/python3.8/site-packages/sqlalchemy/pool/base.py", line 493, in checkout
    rec = pool._do_get()
  File "/home/airflow/.local/lib/python3.8/site-packages/sqlalchemy/pool/impl.py", line 256, in _do_get
    return self._create_connection()
  File "/home/airflow/.local/lib/python3.8/site-packages/sqlalchemy/pool/base.py", line 273, in _create_connection
    return _ConnectionRecord(self)
  File "/home/airflow/.local/lib/python3.8/site-packages/sqlalchemy/pool/base.py", line 388, in __init__
    self.__connect()
  File "/home/airflow/.local/lib/python3.8/site-packages/sqlalchemy/pool/base.py", line 691, in __connect
    pool.logger.debug("Error on connect(): %s", e)
  File "/home/airflow/.local/lib/python3.8/site-packages/sqlalchemy/util/langhelpers.py", line 70, in __exit__
    compat.raise_(
  File "/home/airflow/.local/lib/python3.8/site-packages/sqlalchemy/util/compat.py", line 211, in raise_
    raise exception
  File "/home/airflow/.local/lib/python3.8/site-packages/sqlalchemy/pool/base.py", line 686, in __connect
    self.dbapi_connection = connection = pool._invoke_creator(self)
  File "/home/airflow/.local/lib/python3.8/site-packages/sqlalchemy/engine/create.py", line 574, in connect
    return dialect.connect(*cargs, **cparams)
  File "/home/airflow/.local/lib/python3.8/site-packages/sqlalchemy/engine/default.py", line 598, in connect
    return self.dbapi.connect(*cargs, **cparams)
  File "/home/airflow/.local/lib/python3.8/site-packages/psycopg2/__init__.py", line 122, in connect
    conn = _connect(dsn, connection_factory=connection_factory, **kwasync)
psycopg2.OperationalError: connection to server at "postgres" (172.19.0.2), port 5432 failed: FATAL:  password authentication failed for user "***"


The above exception was the direct cause of the following exception:

Traceback (most recent call last):
  File "/home/airflow/.local/lib/python3.8/site-packages/airflow/jobs/job.py", line 190, in heartbeat
    session.merge(self)
  File "/home/airflow/.local/lib/python3.8/site-packages/sqlalchemy/orm/session.py", line 3056, in merge
    return self._merge(
  File "/home/airflow/.local/lib/python3.8/site-packages/sqlalchemy/orm/session.py", line 3136, in _merge
    merged = self.get(
  File "/home/airflow/.local/lib/python3.8/site-packages/sqlalchemy/orm/session.py", line 2853, in get
    return self._get_impl(
  File "/home/airflow/.local/lib/python3.8/site-packages/sqlalchemy/orm/session.py", line 2975, in _get_impl
    return db_load_fn(
  File "/home/airflow/.local/lib/python3.8/site-packages/sqlalchemy/orm/loading.py", line 530, in load_on_pk_identity
    session.execute(
  File "/home/airflow/.local/lib/python3.8/site-packages/sqlalchemy/orm/session.py", line 1716, in execute
    conn = self._connection_for_bind(bind)
  File "/home/airflow/.local/lib/python3.8/site-packages/sqlalchemy/orm/session.py", line 1555, in _connection_for_bind
    return self._transaction._connection_for_bind(
  File "/home/airflow/.local/lib/python3.8/site-packages/sqlalchemy/orm/session.py", line 750, in _connection_for_bind
    conn = bind.connect()
  File "/home/airflow/.local/lib/python3.8/site-packages/sqlalchemy/future/engine.py", line 406, in connect
    return super(Engine, self).connect()
  File "/home/airflow/.local/lib/python3.8/site-packages/sqlalchemy/engine/base.py", line 3325, in connect
    return self._connection_cls(self, close_with_result=close_with_result)
  File "/home/airflow/.local/lib/python3.8/site-packages/sqlalchemy/engine/base.py", line 96, in __init__
    else engine.raw_connection()
  File "/home/airflow/.local/lib/python3.8/site-packages/sqlalchemy/engine/base.py", line 3404, in raw_connection
    return self._wrap_pool_connect(self.pool.connect, _connection)
  File "/home/airflow/.local/lib/python3.8/site-packages/sqlalchemy/engine/base.py", line 3374, in _wrap_pool_connect
    Connection._handle_dbapi_exception_noconnection(
  File "/home/airflow/.local/lib/python3.8/site-packages/sqlalchemy/engine/base.py", line 2208, in _handle_dbapi_exception_noconnection
    util.raise_(
  File "/home/airflow/.local/lib/python3.8/site-packages/sqlalchemy/util/compat.py", line 211, in raise_
    raise exception
  File "/home/airflow/.local/lib/python3.8/site-packages/sqlalchemy/engine/base.py", line 3371, in _wrap_pool_connect
    return fn()
  File "/home/airflow/.local/lib/python3.8/site-packages/sqlalchemy/pool/base.py", line 327, in connect
    return _ConnectionFairy._checkout(self)
  File "/home/airflow/.local/lib/python3.8/site-packages/sqlalchemy/pool/base.py", line 894, in _checkout
    fairy = _ConnectionRecord.checkout(pool)
  File "/home/airflow/.local/lib/python3.8/site-packages/sqlalchemy/pool/base.py", line 493, in checkout
    rec = pool._do_get()
  File "/home/airflow/.local/lib/python3.8/site-packages/sqlalchemy/pool/impl.py", line 256, in _do_get
    return self._create_connection()
  File "/home/airflow/.local/lib/python3.8/site-packages/sqlalchemy/pool/base.py", line 273, in _create_connection
    return _ConnectionRecord(self)
  File "/home/airflow/.local/lib/python3.8/site-packages/sqlalchemy/pool/base.py", line 388, in __init__
    self.__connect()
  File "/home/airflow/.local/lib/python3.8/site-packages/sqlalchemy/pool/base.py", line 691, in __connect
    pool.logger.debug("Error on connect(): %s", e)
  File "/home/airflow/.local/lib/python3.8/site-packages/sqlalchemy/util/langhelpers.py", line 70, in __exit__
    compat.raise_(
  File "/home/airflow/.local/lib/python3.8/site-packages/sqlalchemy/util/compat.py", line 211, in raise_
    raise exception
  File "/home/airflow/.local/lib/python3.8/site-packages/sqlalchemy/pool/base.py", line 686, in __connect
    self.dbapi_connection = connection = pool._invoke_creator(self)
  File "/home/airflow/.local/lib/python3.8/site-packages/sqlalchemy/engine/create.py", line 574, in connect
    return dialect.connect(*cargs, **cparams)
  File "/home/airflow/.local/lib/python3.8/site-packages/sqlalchemy/engine/default.py", line 598, in connect
    return self.dbapi.connect(*cargs, **cparams)
  File "/home/airflow/.local/lib/python3.8/site-packages/psycopg2/__init__.py", line 122, in connect
    conn = _connect(dsn, connection_factory=connection_factory, **kwasync)
sqlalchemy.exc.OperationalError: (psycopg2.OperationalError) connection to server at "postgres" (172.19.0.2), port 5432 failed: FATAL:  password authentication failed for user "***"

(Background on this error at: https://sqlalche.me/e/14/e3q8)
[2024-08-02T10:32:37.905+0000] {spark_submit.py:579} INFO - 24/08/02 10:32:37 INFO StandaloneAppClient$ClientEndpoint: Connecting to master spark://spark-master:7077...
[2024-08-02T10:32:37.940+0000] {spark_submit.py:579} INFO - 24/08/02 10:32:37 WARN StandaloneAppClient$ClientEndpoint: Failed to connect to master spark-master:7077
[2024-08-02T10:32:37.941+0000] {spark_submit.py:579} INFO - org.apache.spark.SparkException: Exception thrown in awaitResult:
[2024-08-02T10:32:37.941+0000] {spark_submit.py:579} INFO - at org.apache.spark.util.ThreadUtils$.awaitResult(ThreadUtils.scala:301)
[2024-08-02T10:32:37.941+0000] {spark_submit.py:579} INFO - at org.apache.spark.rpc.RpcTimeout.awaitResult(RpcTimeout.scala:75)
[2024-08-02T10:32:37.941+0000] {spark_submit.py:579} INFO - at org.apache.spark.rpc.RpcEnv.setupEndpointRefByURI(RpcEnv.scala:102)
[2024-08-02T10:32:37.941+0000] {spark_submit.py:579} INFO - at org.apache.spark.rpc.RpcEnv.setupEndpointRef(RpcEnv.scala:110)
[2024-08-02T10:32:37.941+0000] {spark_submit.py:579} INFO - at org.apache.spark.deploy.client.StandaloneAppClient$ClientEndpoint$$anon$1.run(StandaloneAppClient.scala:107)
[2024-08-02T10:32:37.942+0000] {spark_submit.py:579} INFO - at java.base/java.util.concurrent.Executors$RunnableAdapter.call(Executors.java:515)
[2024-08-02T10:32:37.942+0000] {spark_submit.py:579} INFO - at java.base/java.util.concurrent.FutureTask.run(FutureTask.java:264)
[2024-08-02T10:32:37.942+0000] {spark_submit.py:579} INFO - at java.base/java.util.concurrent.ThreadPoolExecutor.runWorker(ThreadPoolExecutor.java:1128)
[2024-08-02T10:32:37.942+0000] {spark_submit.py:579} INFO - at java.base/java.util.concurrent.ThreadPoolExecutor$Worker.run(ThreadPoolExecutor.java:628)
[2024-08-02T10:32:37.943+0000] {spark_submit.py:579} INFO - at java.base/java.lang.Thread.run(Thread.java:829)
[2024-08-02T10:32:37.943+0000] {spark_submit.py:579} INFO - Caused by: java.io.IOException: Failed to connect to spark-master:7077
[2024-08-02T10:32:37.959+0000] {spark_submit.py:579} INFO - at org.apache.spark.network.client.TransportClientFactory.createClient(TransportClientFactory.java:298)
[2024-08-02T10:32:37.960+0000] {spark_submit.py:579} INFO - at org.apache.spark.network.client.TransportClientFactory.createClient(TransportClientFactory.java:218)
[2024-08-02T10:32:37.960+0000] {spark_submit.py:579} INFO - at org.apache.spark.network.client.TransportClientFactory.createClient(TransportClientFactory.java:230)
[2024-08-02T10:32:37.961+0000] {spark_submit.py:579} INFO - at org.apache.spark.rpc.netty.NettyRpcEnv.createClient(NettyRpcEnv.scala:204)
[2024-08-02T10:32:37.961+0000] {spark_submit.py:579} INFO - at org.apache.spark.rpc.netty.Outbox$$anon$1.call(Outbox.scala:202)
[2024-08-02T10:32:37.961+0000] {spark_submit.py:579} INFO - at org.apache.spark.rpc.netty.Outbox$$anon$1.call(Outbox.scala:198)
[2024-08-02T10:32:37.965+0000] {spark_submit.py:579} INFO - ... 4 more
[2024-08-02T10:32:37.972+0000] {spark_submit.py:579} INFO - Caused by: java.net.UnknownHostException: spark-master
[2024-08-02T10:32:37.973+0000] {spark_submit.py:579} INFO - at java.base/java.net.InetAddress$CachedAddresses.get(InetAddress.java:797)
[2024-08-02T10:32:37.977+0000] {spark_submit.py:579} INFO - at java.base/java.net.InetAddress.getAllByName0(InetAddress.java:1533)
[2024-08-02T10:32:37.977+0000] {spark_submit.py:579} INFO - at java.base/java.net.InetAddress.getAllByName(InetAddress.java:1386)
[2024-08-02T10:32:37.977+0000] {spark_submit.py:579} INFO - at java.base/java.net.InetAddress.getAllByName(InetAddress.java:1307)
[2024-08-02T10:32:37.978+0000] {spark_submit.py:579} INFO - at java.base/java.net.InetAddress.getByName(InetAddress.java:1257)
[2024-08-02T10:32:37.981+0000] {spark_submit.py:579} INFO - at io.netty.util.internal.SocketUtils$8.run(SocketUtils.java:156)
[2024-08-02T10:32:37.981+0000] {spark_submit.py:579} INFO - at io.netty.util.internal.SocketUtils$8.run(SocketUtils.java:153)
[2024-08-02T10:32:37.985+0000] {spark_submit.py:579} INFO - at java.base/java.security.AccessController.doPrivileged(Native Method)
[2024-08-02T10:32:37.989+0000] {spark_submit.py:579} INFO - at io.netty.util.internal.SocketUtils.addressByName(SocketUtils.java:153)
[2024-08-02T10:32:37.994+0000] {spark_submit.py:579} INFO - at io.netty.resolver.DefaultNameResolver.doResolve(DefaultNameResolver.java:41)
[2024-08-02T10:32:37.994+0000] {spark_submit.py:579} INFO - at io.netty.resolver.SimpleNameResolver.resolve(SimpleNameResolver.java:61)
[2024-08-02T10:32:38.001+0000] {spark_submit.py:579} INFO - at io.netty.resolver.SimpleNameResolver.resolve(SimpleNameResolver.java:53)
[2024-08-02T10:32:38.001+0000] {spark_submit.py:579} INFO - at io.netty.resolver.InetSocketAddressResolver.doResolve(InetSocketAddressResolver.java:55)
[2024-08-02T10:32:38.001+0000] {spark_submit.py:579} INFO - at io.netty.resolver.InetSocketAddressResolver.doResolve(InetSocketAddressResolver.java:31)
[2024-08-02T10:32:38.001+0000] {spark_submit.py:579} INFO - at io.netty.resolver.AbstractAddressResolver.resolve(AbstractAddressResolver.java:106)
[2024-08-02T10:32:38.001+0000] {spark_submit.py:579} INFO - at io.netty.bootstrap.Bootstrap.doResolveAndConnect0(Bootstrap.java:206)
[2024-08-02T10:32:38.003+0000] {spark_submit.py:579} INFO - at io.netty.bootstrap.Bootstrap.access$000(Bootstrap.java:46)
[2024-08-02T10:32:38.007+0000] {spark_submit.py:579} INFO - at io.netty.bootstrap.Bootstrap$1.operationComplete(Bootstrap.java:180)
[2024-08-02T10:32:38.009+0000] {spark_submit.py:579} INFO - at io.netty.bootstrap.Bootstrap$1.operationComplete(Bootstrap.java:166)
[2024-08-02T10:32:38.013+0000] {spark_submit.py:579} INFO - at io.netty.util.concurrent.DefaultPromise.notifyListener0(DefaultPromise.java:578)
[2024-08-02T10:32:38.013+0000] {spark_submit.py:579} INFO - at io.netty.util.concurrent.DefaultPromise.notifyListenersNow(DefaultPromise.java:552)
[2024-08-02T10:32:38.021+0000] {spark_submit.py:579} INFO - at io.netty.util.concurrent.DefaultPromise.notifyListeners(DefaultPromise.java:491)
[2024-08-02T10:32:38.021+0000] {spark_submit.py:579} INFO - at io.netty.util.concurrent.DefaultPromise.setValue0(DefaultPromise.java:616)
[2024-08-02T10:32:38.026+0000] {spark_submit.py:579} INFO - at io.netty.util.concurrent.DefaultPromise.setSuccess0(DefaultPromise.java:605)
[2024-08-02T10:32:38.027+0000] {spark_submit.py:579} INFO - at io.netty.util.concurrent.DefaultPromise.trySuccess(DefaultPromise.java:104)
[2024-08-02T10:32:38.027+0000] {spark_submit.py:579} INFO - at io.netty.channel.DefaultChannelPromise.trySuccess(DefaultChannelPromise.java:84)
[2024-08-02T10:32:38.027+0000] {spark_submit.py:579} INFO - at io.netty.channel.AbstractChannel$AbstractUnsafe.safeSetSuccess(AbstractChannel.java:990)
[2024-08-02T10:32:38.027+0000] {spark_submit.py:579} INFO - at io.netty.channel.AbstractChannel$AbstractUnsafe.register0(AbstractChannel.java:516)
[2024-08-02T10:32:38.027+0000] {spark_submit.py:579} INFO - at io.netty.channel.AbstractChannel$AbstractUnsafe.access$200(AbstractChannel.java:429)
[2024-08-02T10:32:38.029+0000] {spark_submit.py:579} INFO - at io.netty.channel.AbstractChannel$AbstractUnsafe$1.run(AbstractChannel.java:486)
[2024-08-02T10:32:38.029+0000] {spark_submit.py:579} INFO - at io.netty.util.concurrent.AbstractEventExecutor.safeExecute(AbstractEventExecutor.java:164)
[2024-08-02T10:32:38.033+0000] {spark_submit.py:579} INFO - at io.netty.util.concurrent.SingleThreadEventExecutor.runAllTasks(SingleThreadEventExecutor.java:469)
[2024-08-02T10:32:38.033+0000] {spark_submit.py:579} INFO - at io.netty.channel.nio.NioEventLoop.run(NioEventLoop.java:503)
[2024-08-02T10:32:38.033+0000] {spark_submit.py:579} INFO - at io.netty.util.concurrent.SingleThreadEventExecutor$4.run(SingleThreadEventExecutor.java:986)
[2024-08-02T10:32:38.033+0000] {spark_submit.py:579} INFO - at io.netty.util.internal.ThreadExecutorMap$2.run(ThreadExecutorMap.java:74)
[2024-08-02T10:32:38.037+0000] {spark_submit.py:579} INFO - at io.netty.util.concurrent.FastThreadLocalRunnable.run(FastThreadLocalRunnable.java:30)
[2024-08-02T10:32:38.037+0000] {spark_submit.py:579} INFO - ... 1 more
[2024-08-02T10:32:38.272+0000] {job.py:219} ERROR - Job heartbeat got an exception
Traceback (most recent call last):
  File "/home/airflow/.local/lib/python3.8/site-packages/sqlalchemy/engine/base.py", line 3371, in _wrap_pool_connect
    return fn()
  File "/home/airflow/.local/lib/python3.8/site-packages/sqlalchemy/pool/base.py", line 327, in connect
    return _ConnectionFairy._checkout(self)
  File "/home/airflow/.local/lib/python3.8/site-packages/sqlalchemy/pool/base.py", line 894, in _checkout
    fairy = _ConnectionRecord.checkout(pool)
  File "/home/airflow/.local/lib/python3.8/site-packages/sqlalchemy/pool/base.py", line 493, in checkout
    rec = pool._do_get()
  File "/home/airflow/.local/lib/python3.8/site-packages/sqlalchemy/pool/impl.py", line 256, in _do_get
    return self._create_connection()
  File "/home/airflow/.local/lib/python3.8/site-packages/sqlalchemy/pool/base.py", line 273, in _create_connection
    return _ConnectionRecord(self)
  File "/home/airflow/.local/lib/python3.8/site-packages/sqlalchemy/pool/base.py", line 388, in __init__
    self.__connect()
  File "/home/airflow/.local/lib/python3.8/site-packages/sqlalchemy/pool/base.py", line 691, in __connect
    pool.logger.debug("Error on connect(): %s", e)
  File "/home/airflow/.local/lib/python3.8/site-packages/sqlalchemy/util/langhelpers.py", line 70, in __exit__
    compat.raise_(
  File "/home/airflow/.local/lib/python3.8/site-packages/sqlalchemy/util/compat.py", line 211, in raise_
    raise exception
  File "/home/airflow/.local/lib/python3.8/site-packages/sqlalchemy/pool/base.py", line 686, in __connect
    self.dbapi_connection = connection = pool._invoke_creator(self)
  File "/home/airflow/.local/lib/python3.8/site-packages/sqlalchemy/engine/create.py", line 574, in connect
    return dialect.connect(*cargs, **cparams)
  File "/home/airflow/.local/lib/python3.8/site-packages/sqlalchemy/engine/default.py", line 598, in connect
    return self.dbapi.connect(*cargs, **cparams)
  File "/home/airflow/.local/lib/python3.8/site-packages/psycopg2/__init__.py", line 122, in connect
    conn = _connect(dsn, connection_factory=connection_factory, **kwasync)
psycopg2.OperationalError: connection to server at "postgres" (172.19.0.2), port 5432 failed: FATAL:  password authentication failed for user "***"


The above exception was the direct cause of the following exception:

Traceback (most recent call last):
  File "/home/airflow/.local/lib/python3.8/site-packages/airflow/jobs/job.py", line 190, in heartbeat
    session.merge(self)
  File "/home/airflow/.local/lib/python3.8/site-packages/sqlalchemy/orm/session.py", line 3056, in merge
    return self._merge(
  File "/home/airflow/.local/lib/python3.8/site-packages/sqlalchemy/orm/session.py", line 3136, in _merge
    merged = self.get(
  File "/home/airflow/.local/lib/python3.8/site-packages/sqlalchemy/orm/session.py", line 2853, in get
    return self._get_impl(
  File "/home/airflow/.local/lib/python3.8/site-packages/sqlalchemy/orm/session.py", line 2975, in _get_impl
    return db_load_fn(
  File "/home/airflow/.local/lib/python3.8/site-packages/sqlalchemy/orm/loading.py", line 530, in load_on_pk_identity
    session.execute(
  File "/home/airflow/.local/lib/python3.8/site-packages/sqlalchemy/orm/session.py", line 1716, in execute
    conn = self._connection_for_bind(bind)
  File "/home/airflow/.local/lib/python3.8/site-packages/sqlalchemy/orm/session.py", line 1555, in _connection_for_bind
    return self._transaction._connection_for_bind(
  File "/home/airflow/.local/lib/python3.8/site-packages/sqlalchemy/orm/session.py", line 750, in _connection_for_bind
    conn = bind.connect()
  File "/home/airflow/.local/lib/python3.8/site-packages/sqlalchemy/future/engine.py", line 406, in connect
    return super(Engine, self).connect()
  File "/home/airflow/.local/lib/python3.8/site-packages/sqlalchemy/engine/base.py", line 3325, in connect
    return self._connection_cls(self, close_with_result=close_with_result)
  File "/home/airflow/.local/lib/python3.8/site-packages/sqlalchemy/engine/base.py", line 96, in __init__
    else engine.raw_connection()
  File "/home/airflow/.local/lib/python3.8/site-packages/sqlalchemy/engine/base.py", line 3404, in raw_connection
    return self._wrap_pool_connect(self.pool.connect, _connection)
  File "/home/airflow/.local/lib/python3.8/site-packages/sqlalchemy/engine/base.py", line 3374, in _wrap_pool_connect
    Connection._handle_dbapi_exception_noconnection(
  File "/home/airflow/.local/lib/python3.8/site-packages/sqlalchemy/engine/base.py", line 2208, in _handle_dbapi_exception_noconnection
    util.raise_(
  File "/home/airflow/.local/lib/python3.8/site-packages/sqlalchemy/util/compat.py", line 211, in raise_
    raise exception
  File "/home/airflow/.local/lib/python3.8/site-packages/sqlalchemy/engine/base.py", line 3371, in _wrap_pool_connect
    return fn()
  File "/home/airflow/.local/lib/python3.8/site-packages/sqlalchemy/pool/base.py", line 327, in connect
    return _ConnectionFairy._checkout(self)
  File "/home/airflow/.local/lib/python3.8/site-packages/sqlalchemy/pool/base.py", line 894, in _checkout
    fairy = _ConnectionRecord.checkout(pool)
  File "/home/airflow/.local/lib/python3.8/site-packages/sqlalchemy/pool/base.py", line 493, in checkout
    rec = pool._do_get()
  File "/home/airflow/.local/lib/python3.8/site-packages/sqlalchemy/pool/impl.py", line 256, in _do_get
    return self._create_connection()
  File "/home/airflow/.local/lib/python3.8/site-packages/sqlalchemy/pool/base.py", line 273, in _create_connection
    return _ConnectionRecord(self)
  File "/home/airflow/.local/lib/python3.8/site-packages/sqlalchemy/pool/base.py", line 388, in __init__
    self.__connect()
  File "/home/airflow/.local/lib/python3.8/site-packages/sqlalchemy/pool/base.py", line 691, in __connect
    pool.logger.debug("Error on connect(): %s", e)
  File "/home/airflow/.local/lib/python3.8/site-packages/sqlalchemy/util/langhelpers.py", line 70, in __exit__
    compat.raise_(
  File "/home/airflow/.local/lib/python3.8/site-packages/sqlalchemy/util/compat.py", line 211, in raise_
    raise exception
  File "/home/airflow/.local/lib/python3.8/site-packages/sqlalchemy/pool/base.py", line 686, in __connect
    self.dbapi_connection = connection = pool._invoke_creator(self)
  File "/home/airflow/.local/lib/python3.8/site-packages/sqlalchemy/engine/create.py", line 574, in connect
    return dialect.connect(*cargs, **cparams)
  File "/home/airflow/.local/lib/python3.8/site-packages/sqlalchemy/engine/default.py", line 598, in connect
    return self.dbapi.connect(*cargs, **cparams)
  File "/home/airflow/.local/lib/python3.8/site-packages/psycopg2/__init__.py", line 122, in connect
    conn = _connect(dsn, connection_factory=connection_factory, **kwasync)
sqlalchemy.exc.OperationalError: (psycopg2.OperationalError) connection to server at "postgres" (172.19.0.2), port 5432 failed: FATAL:  password authentication failed for user "***"

(Background on this error at: https://sqlalche.me/e/14/e3q8)
[2024-08-02T10:32:43.311+0000] {job.py:219} ERROR - Job heartbeat got an exception
Traceback (most recent call last):
  File "/home/airflow/.local/lib/python3.8/site-packages/sqlalchemy/engine/base.py", line 3371, in _wrap_pool_connect
    return fn()
  File "/home/airflow/.local/lib/python3.8/site-packages/sqlalchemy/pool/base.py", line 327, in connect
    return _ConnectionFairy._checkout(self)
  File "/home/airflow/.local/lib/python3.8/site-packages/sqlalchemy/pool/base.py", line 894, in _checkout
    fairy = _ConnectionRecord.checkout(pool)
  File "/home/airflow/.local/lib/python3.8/site-packages/sqlalchemy/pool/base.py", line 493, in checkout
    rec = pool._do_get()
  File "/home/airflow/.local/lib/python3.8/site-packages/sqlalchemy/pool/impl.py", line 256, in _do_get
    return self._create_connection()
  File "/home/airflow/.local/lib/python3.8/site-packages/sqlalchemy/pool/base.py", line 273, in _create_connection
    return _ConnectionRecord(self)
  File "/home/airflow/.local/lib/python3.8/site-packages/sqlalchemy/pool/base.py", line 388, in __init__
    self.__connect()
  File "/home/airflow/.local/lib/python3.8/site-packages/sqlalchemy/pool/base.py", line 691, in __connect
    pool.logger.debug("Error on connect(): %s", e)
  File "/home/airflow/.local/lib/python3.8/site-packages/sqlalchemy/util/langhelpers.py", line 70, in __exit__
    compat.raise_(
  File "/home/airflow/.local/lib/python3.8/site-packages/sqlalchemy/util/compat.py", line 211, in raise_
    raise exception
  File "/home/airflow/.local/lib/python3.8/site-packages/sqlalchemy/pool/base.py", line 686, in __connect
    self.dbapi_connection = connection = pool._invoke_creator(self)
  File "/home/airflow/.local/lib/python3.8/site-packages/sqlalchemy/engine/create.py", line 574, in connect
    return dialect.connect(*cargs, **cparams)
  File "/home/airflow/.local/lib/python3.8/site-packages/sqlalchemy/engine/default.py", line 598, in connect
    return self.dbapi.connect(*cargs, **cparams)
  File "/home/airflow/.local/lib/python3.8/site-packages/psycopg2/__init__.py", line 122, in connect
    conn = _connect(dsn, connection_factory=connection_factory, **kwasync)
psycopg2.OperationalError: connection to server at "postgres" (172.19.0.2), port 5432 failed: FATAL:  password authentication failed for user "***"


The above exception was the direct cause of the following exception:

Traceback (most recent call last):
  File "/home/airflow/.local/lib/python3.8/site-packages/airflow/jobs/job.py", line 190, in heartbeat
    session.merge(self)
  File "/home/airflow/.local/lib/python3.8/site-packages/sqlalchemy/orm/session.py", line 3056, in merge
    return self._merge(
  File "/home/airflow/.local/lib/python3.8/site-packages/sqlalchemy/orm/session.py", line 3136, in _merge
    merged = self.get(
  File "/home/airflow/.local/lib/python3.8/site-packages/sqlalchemy/orm/session.py", line 2853, in get
    return self._get_impl(
  File "/home/airflow/.local/lib/python3.8/site-packages/sqlalchemy/orm/session.py", line 2975, in _get_impl
    return db_load_fn(
  File "/home/airflow/.local/lib/python3.8/site-packages/sqlalchemy/orm/loading.py", line 530, in load_on_pk_identity
    session.execute(
  File "/home/airflow/.local/lib/python3.8/site-packages/sqlalchemy/orm/session.py", line 1716, in execute
    conn = self._connection_for_bind(bind)
  File "/home/airflow/.local/lib/python3.8/site-packages/sqlalchemy/orm/session.py", line 1555, in _connection_for_bind
    return self._transaction._connection_for_bind(
  File "/home/airflow/.local/lib/python3.8/site-packages/sqlalchemy/orm/session.py", line 750, in _connection_for_bind
    conn = bind.connect()
  File "/home/airflow/.local/lib/python3.8/site-packages/sqlalchemy/future/engine.py", line 406, in connect
    return super(Engine, self).connect()
  File "/home/airflow/.local/lib/python3.8/site-packages/sqlalchemy/engine/base.py", line 3325, in connect
    return self._connection_cls(self, close_with_result=close_with_result)
  File "/home/airflow/.local/lib/python3.8/site-packages/sqlalchemy/engine/base.py", line 96, in __init__
    else engine.raw_connection()
  File "/home/airflow/.local/lib/python3.8/site-packages/sqlalchemy/engine/base.py", line 3404, in raw_connection
    return self._wrap_pool_connect(self.pool.connect, _connection)
  File "/home/airflow/.local/lib/python3.8/site-packages/sqlalchemy/engine/base.py", line 3374, in _wrap_pool_connect
    Connection._handle_dbapi_exception_noconnection(
  File "/home/airflow/.local/lib/python3.8/site-packages/sqlalchemy/engine/base.py", line 2208, in _handle_dbapi_exception_noconnection
    util.raise_(
  File "/home/airflow/.local/lib/python3.8/site-packages/sqlalchemy/util/compat.py", line 211, in raise_
    raise exception
  File "/home/airflow/.local/lib/python3.8/site-packages/sqlalchemy/engine/base.py", line 3371, in _wrap_pool_connect
    return fn()
  File "/home/airflow/.local/lib/python3.8/site-packages/sqlalchemy/pool/base.py", line 327, in connect
    return _ConnectionFairy._checkout(self)
  File "/home/airflow/.local/lib/python3.8/site-packages/sqlalchemy/pool/base.py", line 894, in _checkout
    fairy = _ConnectionRecord.checkout(pool)
  File "/home/airflow/.local/lib/python3.8/site-packages/sqlalchemy/pool/base.py", line 493, in checkout
    rec = pool._do_get()
  File "/home/airflow/.local/lib/python3.8/site-packages/sqlalchemy/pool/impl.py", line 256, in _do_get
    return self._create_connection()
  File "/home/airflow/.local/lib/python3.8/site-packages/sqlalchemy/pool/base.py", line 273, in _create_connection
    return _ConnectionRecord(self)
  File "/home/airflow/.local/lib/python3.8/site-packages/sqlalchemy/pool/base.py", line 388, in __init__
    self.__connect()
  File "/home/airflow/.local/lib/python3.8/site-packages/sqlalchemy/pool/base.py", line 691, in __connect
    pool.logger.debug("Error on connect(): %s", e)
  File "/home/airflow/.local/lib/python3.8/site-packages/sqlalchemy/util/langhelpers.py", line 70, in __exit__
    compat.raise_(
  File "/home/airflow/.local/lib/python3.8/site-packages/sqlalchemy/util/compat.py", line 211, in raise_
    raise exception
  File "/home/airflow/.local/lib/python3.8/site-packages/sqlalchemy/pool/base.py", line 686, in __connect
    self.dbapi_connection = connection = pool._invoke_creator(self)
  File "/home/airflow/.local/lib/python3.8/site-packages/sqlalchemy/engine/create.py", line 574, in connect
    return dialect.connect(*cargs, **cparams)
  File "/home/airflow/.local/lib/python3.8/site-packages/sqlalchemy/engine/default.py", line 598, in connect
    return self.dbapi.connect(*cargs, **cparams)
  File "/home/airflow/.local/lib/python3.8/site-packages/psycopg2/__init__.py", line 122, in connect
    conn = _connect(dsn, connection_factory=connection_factory, **kwasync)
sqlalchemy.exc.OperationalError: (psycopg2.OperationalError) connection to server at "postgres" (172.19.0.2), port 5432 failed: FATAL:  password authentication failed for user "***"

(Background on this error at: https://sqlalche.me/e/14/e3q8)
